<mujoco model="cart-pole">
  <compiler angle="radian" meshdir="assets" texturedir="assets" autolimits="true" />

  <include file="./skybox.xml"/>
  <include file="./visual.xml"/>
  <include file="./materials.xml"/>

  <option timestep="0.002" integrator="RK4">
    <flag contact="disable" energy="enable" sensornoise="enable" />
  </option>

  <default>
    <default class="pole">
      <joint type="hinge" axis="0 1 0" damping="2e-6"/>
      <geom type="capsule" fromto="0 0 0 0 0 1" size="0.045" material="self" mass="0.1"/>
    </default>
  </default>

  <worldbody>
    <light name="light" pos="0 0 6"/>
    <camera name="fixed" pos="0 -4 1" zaxis="0 -1 0"/>
    <camera name="lookatcart" mode="targetbody" target="cart" pos="0 -2 2"/>
    <geom name="floor" pos="0 0 -1.5" size="4 4 .2" type="plane" material="grid"/>
    <geom name="rail1" type="capsule" pos="0  .07 1" zaxis="1 0 0" size="0.02 4" material="decoration" />
    <geom name="rail2" type="capsule" pos="0 -.07 1" zaxis="1 0 0" size="0.02 4" material="decoration" />
    <body name="cart" pos="0 0 1">
      <site name="cart" />
      <joint name="slider" type="slide" limited="true" axis="1 0 0" range="-4.8 4.8" solreflimit=".08 1" damping="5e-4"/>
      <geom name="cart" type="box" size="0.2 0.15 0.1" material="self" mass="1"/>
      <body name="pole_1" childclass="pole">
        <joint name="hinge_1"/>
        <geom name="pole_1"/>
        <!-- <body name="pole_2" pos="0 0 1" childclass="pole">
          <joint name="hinge_2"/>
          <geom name="pole_2"/>
        </body> -->
      </body>
    </body>
  </worldbody>

  <actuator>
    <motor name="slide" joint="slider" gear="1" ctrllimited="true" ctrlrange="-1000 1000" />
  </actuator>

  <sensor>
    <jointpos name="pos_slider" joint="slider" noise="0.0" />
    <jointpos name="pos_hinge_1" joint="hinge_1" noise="0.0" />

    <jointvel name="vel_slider" joint="slider" noise="0.0" />
    <jointvel name="vel_hinge_1" joint="hinge_1" noise="0.0" />
    <!-- <jointpos name="pos_hinge_2" joint="hinge_2" noise="0.0" />
    <jointvel name="vel_hinge_2" joint="hinge_2" noise="0.0" /> -->
  </sensor>

</mujoco>
